<?xml version="1.0" ?>
<!-- =================================================================================== -->
<!-- |    This document was autogenerated by xacro from /home/wy/RS/A3/el_a3_description/urdf/el_a3.urdf.xacro | -->
<!-- |    EDITING THIS FILE BY HAND IS NOT RECOMMENDED                                 | -->
<!-- =================================================================================== -->
<!-- EL-A3 6-DOF Robot Arm URDF with ros2_control support -->
<!-- Updated from EDULITE-A3 model -->
<robot name="EL-A3">
  <!-- Materials -->
  <material name="orange">
    <color rgba="0.972549 0.529412 0.00392157 1"/>
  </material>
  <material name="gray">
    <color rgba="0.647059 0.647059 0.647059 1"/>
  </material>
  <material name="light_blue">
    <color rgba="0.768627 0.886275 0.952941 1"/>
  </material>
  <material name="white">
    <color rgba="0.917647 0.917647 0.917647 1"/>
  </material>
  <material name="dark_gray">
    <color rgba="0.301961 0.301961 0.301961 1"/>
  </material>
  <material name="blue">
    <color rgba="0.231373 0.380392 0.705882 1"/>
  </material>
  <material name="yellow">
    <color rgba="0.980392 0.713725 0.00392157 1"/>
  </material>
  <material name="green">
    <color rgba="0.372549 0.654902 0.239216 1"/>
  </material>
  <!-- Base link (world) -->
  <link name="base_link"/>
  <joint name="base_to_l1" type="fixed">
    <parent link="base_link"/>
    <child link="l1_urdf_urdf_asm"/>
    <origin rpy="0 0 0" xyz="0 0 0"/>
  </joint>
  <!-- Link l1_urdf_urdf_asm (Base) -->
  <link name="l1_urdf_urdf_asm">
    <inertial>
      <origin rpy="0 0 0" xyz="-2.68984e-10 1.48294e-05 -0.0220571"/>
      <mass value="0.465144"/>
      <inertia ixx="0.00032748" ixy="-1.33894e-08" ixz="-1.85358e-12" iyy="0.000321793" iyz="-2.46949e-07" izz="0.000362426"/>
    </inertial>
    <!-- Part part_10 -->
    <visual>
      <origin rpy="0 0 0" xyz="0 0 0"/>
      <geometry>
        <mesh filename="package://el_a3_description/meshes/part_10.stl"/>
      </geometry>
      <material name="green"/>
    </visual>
    <collision>
      <origin rpy="0 0 0" xyz="0 0 0"/>
      <geometry>
        <mesh filename="package://el_a3_description/meshes/part_10.stl"/>
      </geometry>
    </collision>
    <!-- Part rs00_l1 -->
    <visual>
      <origin rpy="0 0 0" xyz="0 0 0"/>
      <geometry>
        <mesh filename="package://el_a3_description/meshes/rs00_l1.stl"/>
      </geometry>
      <material name="orange"/>
    </visual>
    <collision>
      <origin rpy="0 0 0" xyz="0 0 0"/>
      <geometry>
        <mesh filename="package://el_a3_description/meshes/rs00_l1.stl"/>
      </geometry>
    </collision>
  </link>
  <!-- Link l1_link_urdf_asm -->
  <link name="l1_link_urdf_asm">
    <inertial>
      <origin rpy="0 0 0" xyz="-0.00202103 -0.00162495 0.0394318"/>
      <mass value="0.146738"/>
      <inertia ixx="0.000221617" ixy="-1.44161e-06" ixz="1.46922e-05" iyy="0.000129193" iyz="4.22954e-06" izz="0.000175411"/>
    </inertial>
    <!-- Part part_8 -->
    <visual>
      <origin rpy="0 0 0" xyz="0 0 -0.006"/>
      <geometry>
        <mesh filename="package://el_a3_description/meshes/part_8.stl"/>
      </geometry>
      <material name="yellow"/>
    </visual>
    <collision>
      <origin rpy="0 0 0" xyz="0 0 -0.006"/>
      <geometry>
        <mesh filename="package://el_a3_description/meshes/part_8.stl"/>
      </geometry>
    </collision>
    <!-- Part part_9 -->
    <visual>
      <origin rpy="0 0 0" xyz="0 0 -0.006"/>
      <geometry>
        <mesh filename="package://el_a3_description/meshes/part_9.stl"/>
      </geometry>
      <material name="yellow"/>
    </visual>
    <collision>
      <origin rpy="0 0 0" xyz="0 0 -0.006"/>
      <geometry>
        <mesh filename="package://el_a3_description/meshes/part_9.stl"/>
      </geometry>
    </collision>
  </link>
  <!-- Link l2_l3_urdf_asm -->
  <link name="l2_l3_urdf_asm">
    <inertial>
      <origin rpy="0 0 0" xyz="0.0949994 -1.38262e-06 -0.00108795"/>
      <mass value="0.946534"/>
      <inertia ixx="0.000493341" ixy="6.92125e-07" ixz="-1.27006e-08" iyy="0.00767087" iyz="2.73309e-09" izz="0.0076934"/>
    </inertial>
    <!-- Part mainlink_back -->
    <visual>
      <origin rpy="-1.5708 0 0" xyz="0.01 -0.07 -0.0001"/>
      <geometry>
        <mesh filename="package://el_a3_description/meshes/mainlink_back.stl"/>
      </geometry>
      <material name="gray"/>
    </visual>
    <collision>
      <origin rpy="-1.5708 0 0" xyz="0.01 -0.07 -0.0001"/>
      <geometry>
        <mesh filename="package://el_a3_description/meshes/mainlink_back.stl"/>
      </geometry>
    </collision>
    <!-- Part 6705 -->
    <visual>
      <origin rpy="-1.5708 0 0" xyz="0.01 -0.07 -0.0001"/>
      <geometry>
        <mesh filename="package://el_a3_description/meshes/6705.stl"/>
      </geometry>
      <material name="white"/>
    </visual>
    <collision>
      <origin rpy="-1.5708 0 0" xyz="0.01 -0.07 -0.0001"/>
      <geometry>
        <mesh filename="package://el_a3_description/meshes/6705.stl"/>
      </geometry>
    </collision>
    <!-- Part rs00_l2 -->
    <visual>
      <origin rpy="-1.5708 0 0" xyz="0.01 -0.07 -0.0006"/>
      <geometry>
        <mesh filename="package://el_a3_description/meshes/rs00_l2.stl"/>
      </geometry>
      <material name="orange"/>
    </visual>
    <collision>
      <origin rpy="-1.5708 0 0" xyz="0.01 -0.07 -0.0006"/>
      <geometry>
        <mesh filename="package://el_a3_description/meshes/rs00_l2.stl"/>
      </geometry>
    </collision>
    <!-- Part mainlink_motor -->
    <visual>
      <origin rpy="-1.5708 0 0" xyz="0.01 -0.07 -0.0006"/>
      <geometry>
        <mesh filename="package://el_a3_description/meshes/mainlink_motor.stl"/>
      </geometry>
      <material name="gray"/>
    </visual>
    <collision>
      <origin rpy="-1.5708 0 0" xyz="0.01 -0.07 -0.0006"/>
      <geometry>
        <mesh filename="package://el_a3_description/meshes/mainlink_motor.stl"/>
      </geometry>
    </collision>
    <!-- Part 6705_2 -->
    <visual>
      <origin rpy="-1.5708 0 0" xyz="0.01 -0.07 -0.0001"/>
      <geometry>
        <mesh filename="package://el_a3_description/meshes/6705__2.stl"/>
      </geometry>
      <material name="blue"/>
    </visual>
    <collision>
      <origin rpy="-1.5708 0 0" xyz="0.01 -0.07 -0.0001"/>
      <geometry>
        <mesh filename="package://el_a3_description/meshes/6705__2.stl"/>
      </geometry>
    </collision>
    <!-- Part rs00_l3 -->
    <visual>
      <origin rpy="-1.5708 0 0" xyz="0.01 -0.07 -0.0006"/>
      <geometry>
        <mesh filename="package://el_a3_description/meshes/rs00_l3.stl"/>
      </geometry>
      <material name="orange"/>
    </visual>
    <collision>
      <origin rpy="-1.5708 0 0" xyz="0.01 -0.07 -0.0006"/>
      <geometry>
        <mesh filename="package://el_a3_description/meshes/rs00_l3.stl"/>
      </geometry>
    </collision>
  </link>
  <!-- Link l3_lnik_urdf_asm -->
  <link name="l3_lnik_urdf_asm">
    <inertial>
      <origin rpy="0 0 0" xyz="-0.0693243 0.0530595 -0.0510805"/>
      <mass value="0.406558"/>
      <inertia ixx="0.000554036" ixy="0.000274809" ixz="4.74842e-06" iyy="0.00189339" iyz="7.79959e-06" izz="0.00192037"/>
    </inertial>
    <!-- Part small_arm_right -->
    <visual>
      <origin rpy="-1.5708 0 0" xyz="-0.18 -0.07 -0.0518"/>
      <geometry>
        <mesh filename="package://el_a3_description/meshes/small_arm_right.stl"/>
      </geometry>
      <material name="orange"/>
    </visual>
    <collision>
      <origin rpy="-1.5708 0 0" xyz="-0.18 -0.07 -0.0518"/>
      <geometry>
        <mesh filename="package://el_a3_description/meshes/small_arm_right.stl"/>
      </geometry>
    </collision>
    <!-- Part small_arm_left -->
    <visual>
      <origin rpy="-1.5708 0 0" xyz="-0.18 -0.07 -0.0518"/>
      <geometry>
        <mesh filename="package://el_a3_description/meshes/small_arm_left.stl"/>
      </geometry>
      <material name="orange"/>
    </visual>
    <collision>
      <origin rpy="-1.5708 0 0" xyz="-0.18 -0.07 -0.0518"/>
      <geometry>
        <mesh filename="package://el_a3_description/meshes/small_arm_left.stl"/>
      </geometry>
    </collision>
  </link>
  <!-- Link l4_l5_urdf_asm -->
  <link name="l4_l5_urdf_asm">
    <inertial>
      <origin rpy="0 0 0" xyz="-0.0241077 0.0297756 -0.000254349"/>
      <mass value="0.54692"/>
      <inertia ixx="0.000543249" ixy="0.000320527" ixz="2.88671e-06" iyy="0.00040341" iyz="-3.57587e-06" izz="0.000797799"/>
    </inertial>
    <!-- Part el05_l5 -->
    <visual>
      <origin rpy="-1.5708 0 0" xyz="0.005 -0.134 0"/>
      <geometry>
        <mesh filename="package://el_a3_description/meshes/el05_l5.stl"/>
      </geometry>
      <material name="white"/>
    </visual>
    <collision>
      <origin rpy="-1.5708 0 0" xyz="0.005 -0.134 0"/>
      <geometry>
        <mesh filename="package://el_a3_description/meshes/el05_l5.stl"/>
      </geometry>
    </collision>
    <!-- Part l5_shake -->
    <visual>
      <origin rpy="-1.5708 0 0" xyz="0.005 -0.134 0"/>
      <geometry>
        <mesh filename="package://el_a3_description/meshes/l5_shake.stl"/>
      </geometry>
      <material name="light_blue"/>
    </visual>
    <collision>
      <origin rpy="-1.5708 0 0" xyz="0.005 -0.134 0"/>
      <geometry>
        <mesh filename="package://el_a3_description/meshes/l5_shake.stl"/>
      </geometry>
    </collision>
    <!-- Part l4_l5_link_back -->
    <visual>
      <origin rpy="-1.5708 0 0" xyz="0.005 -0.134 0"/>
      <geometry>
        <mesh filename="package://el_a3_description/meshes/l4_l5_link_back.stl"/>
      </geometry>
      <material name="orange"/>
    </visual>
    <collision>
      <origin rpy="-1.5708 0 0" xyz="0.005 -0.134 0"/>
      <geometry>
        <mesh filename="package://el_a3_description/meshes/l4_l5_link_back.stl"/>
      </geometry>
    </collision>
    <!-- Part el05_l4 -->
    <visual>
      <origin rpy="-1.5708 0 0" xyz="0.005 -0.134 0"/>
      <geometry>
        <mesh filename="package://el_a3_description/meshes/el05_l4.stl"/>
      </geometry>
      <material name="white"/>
    </visual>
    <collision>
      <origin rpy="-1.5708 0 0" xyz="0.005 -0.134 0"/>
      <geometry>
        <mesh filename="package://el_a3_description/meshes/el05_l4.stl"/>
      </geometry>
    </collision>
    <!-- Part l4_l5_link_back_2 -->
    <visual>
      <origin rpy="-1.5708 0 0" xyz="0.005 -0.134 0"/>
      <geometry>
        <mesh filename="package://el_a3_description/meshes/l4_l5_link_back__2.stl"/>
      </geometry>
      <material name="orange"/>
    </visual>
    <collision>
      <origin rpy="-1.5708 0 0" xyz="0.005 -0.134 0"/>
      <geometry>
        <mesh filename="package://el_a3_description/meshes/l4_l5_link_back__2.stl"/>
      </geometry>
    </collision>
  </link>
  <!-- Link part_9 -->
  <link name="part_9">
    <inertial>
      <origin rpy="0 0 0" xyz="0.00409255 0 0.0175119"/>
      <mass value="0.031"/>
      <inertia ixx="5.21252e-06" ixy="0" ixz="-1.22446e-06" iyy="5.09672e-06" iyz="0" izz="2.51083e-06"/>
    </inertial>
    <!-- Part part_9_2 -->
    <visual>
      <origin rpy="3.14159 0 0" xyz="0.0542 0 0.172"/>
      <geometry>
        <mesh filename="package://el_a3_description/meshes/part_9__2.stl"/>
      </geometry>
      <material name="orange"/>
    </visual>
    <collision>
      <origin rpy="3.14159 0 0" xyz="0.0542 0 0.172"/>
      <geometry>
        <mesh filename="package://el_a3_description/meshes/part_9__2.stl"/>
      </geometry>
    </collision>
  </link>
  <!-- Link l5_l6_urdf_asm (End Effector) -->
  <link name="l5_l6_urdf_asm">
    <inertial>
      <origin rpy="0 0 0" xyz="-1.16996e-05 0.000627615 -0.0701883"/>
      <mass value="0.6317"/>
      <inertia ixx="0.00100405" ixy="-4.97095e-06" ixz="1.06714e-07" iyy="0.00139953" iyz="1.65952e-05" izz="0.00054217"/>
    </inertial>
    <!-- Part part_4 -->
    <visual>
      <origin rpy="3.14159 -1.5708 0" xyz="0 0 -0.062"/>
      <geometry>
        <mesh filename="package://el_a3_description/meshes/part_4.stl"/>
      </geometry>
      <material name="gray"/>
    </visual>
    <collision>
      <origin rpy="3.14159 -1.5708 0" xyz="0 0 -0.062"/>
      <geometry>
        <mesh filename="package://el_a3_description/meshes/part_4.stl"/>
      </geometry>
    </collision>
    <!-- Part hand_r -->
    <visual>
      <origin rpy="3.14159 0 0" xyz="0 0 -0.0755"/>
      <geometry>
        <mesh filename="package://el_a3_description/meshes/hand_r.stl"/>
      </geometry>
      <material name="blue"/>
    </visual>
    <collision>
      <origin rpy="3.14159 0 0" xyz="0 0 -0.0755"/>
      <geometry>
        <mesh filename="package://el_a3_description/meshes/hand_r.stl"/>
      </geometry>
    </collision>
    <!-- Part el05 -->
    <visual>
      <origin rpy="-3.14159 0 0" xyz="0 0 -0.0755"/>
      <geometry>
        <mesh filename="package://el_a3_description/meshes/el05.stl"/>
      </geometry>
      <material name="white"/>
    </visual>
    <collision>
      <origin rpy="-3.14159 0 0" xyz="0 0 -0.0755"/>
      <geometry>
        <mesh filename="package://el_a3_description/meshes/el05.stl"/>
      </geometry>
    </collision>
    <!-- Part rack__30_teeth -->
    <visual>
      <origin rpy="-3.14159 0 0" xyz="0 0 -0.0755"/>
      <geometry>
        <mesh filename="package://el_a3_description/meshes/rack__30_teeth.stl"/>
      </geometry>
      <material name="white"/>
    </visual>
    <collision>
      <origin rpy="-3.14159 0 0" xyz="0 0 -0.0755"/>
      <geometry>
        <mesh filename="package://el_a3_description/meshes/rack__30_teeth.stl"/>
      </geometry>
    </collision>
    <!-- Part manifold_solid_brep_39_1 -->
    <visual>
      <origin rpy="-3.14159 0 0" xyz="0.003 0 -0.0755"/>
      <geometry>
        <mesh filename="package://el_a3_description/meshes/manifold_solid_brep_39_1.stl"/>
      </geometry>
      <material name="yellow"/>
    </visual>
    <collision>
      <origin rpy="-3.14159 0 0" xyz="0.003 0 -0.0755"/>
      <geometry>
        <mesh filename="package://el_a3_description/meshes/manifold_solid_brep_39_1.stl"/>
      </geometry>
    </collision>
    <!-- Part rack__30_teeth_2 -->
    <visual>
      <origin rpy="-3.14159 0 0" xyz="0 0 -0.0755"/>
      <geometry>
        <mesh filename="package://el_a3_description/meshes/rack__30_teeth__2.stl"/>
      </geometry>
      <material name="white"/>
    </visual>
    <collision>
      <origin rpy="-3.14159 0 0" xyz="0 0 -0.0755"/>
      <geometry>
        <mesh filename="package://el_a3_description/meshes/rack__30_teeth__2.stl"/>
      </geometry>
    </collision>
    <!-- Part manifold_solid_brep_39_1_2 -->
    <visual>
      <origin rpy="-3.14159 0 0" xyz="-0.003 0 -0.0755"/>
      <geometry>
        <mesh filename="package://el_a3_description/meshes/manifold_solid_brep_39_1__2.stl"/>
      </geometry>
      <material name="yellow"/>
    </visual>
    <collision>
      <origin rpy="-3.14159 0 0" xyz="-0.003 0 -0.0755"/>
      <geometry>
        <mesh filename="package://el_a3_description/meshes/manifold_solid_brep_39_1__2.stl"/>
      </geometry>
    </collision>
    <!-- Part rack_base -->
    <visual>
      <origin rpy="-3.14159 0 0" xyz="0 0 -0.0755"/>
      <geometry>
        <mesh filename="package://el_a3_description/meshes/rack_base.stl"/>
      </geometry>
      <material name="light_blue"/>
    </visual>
    <collision>
      <origin rpy="-3.14159 0 0" xyz="0 0 -0.0755"/>
      <geometry>
        <mesh filename="package://el_a3_description/meshes/rack_base.stl"/>
      </geometry>
    </collision>
    <!-- Part rack_str -->
    <visual>
      <origin rpy="-3.14159 0 0" xyz="0 0 -0.0755"/>
      <geometry>
        <mesh filename="package://el_a3_description/meshes/rack_str.stl"/>
      </geometry>
      <material name="light_blue"/>
    </visual>
    <collision>
      <origin rpy="-3.14159 0 0" xyz="0 0 -0.0755"/>
      <geometry>
        <mesh filename="package://el_a3_description/meshes/rack_str.stl"/>
      </geometry>
    </collision>
    <!-- Part part_3 -->
    <visual>
      <origin rpy="3.14159 -1.5708 0" xyz="0 0 -0.062"/>
      <geometry>
        <mesh filename="package://el_a3_description/meshes/part_3.stl"/>
      </geometry>
      <material name="light_blue"/>
    </visual>
    <collision>
      <origin rpy="3.14159 -1.5708 0" xyz="0 0 -0.062"/>
      <geometry>
        <mesh filename="package://el_a3_description/meshes/part_3.stl"/>
      </geometry>
    </collision>
    <!-- Part el05_2 -->
    <visual>
      <origin rpy="0 0 0" xyz="0 0 -0.0305"/>
      <geometry>
        <mesh filename="package://el_a3_description/meshes/el05.stl"/>
      </geometry>
      <material name="white"/>
    </visual>
    <collision>
      <origin rpy="0 0 0" xyz="0 0 -0.0305"/>
      <geometry>
        <mesh filename="package://el_a3_description/meshes/el05.stl"/>
      </geometry>
    </collision>
    <!-- Part spur_gear__14_teeth -->
    <visual>
      <origin rpy="-3.14159 0 0" xyz="0 0 -0.0755"/>
      <geometry>
        <mesh filename="package://el_a3_description/meshes/spur_gear__14_teeth.stl"/>
      </geometry>
      <material name="white"/>
    </visual>
    <collision>
      <origin rpy="-3.14159 0 0" xyz="0 0 -0.0755"/>
      <geometry>
        <mesh filename="package://el_a3_description/meshes/spur_gear__14_teeth.stl"/>
      </geometry>
    </collision>
    <!-- Part part_15 -->
    <visual>
      <origin rpy="-3.14159 0 0" xyz="0 0 -0.0755"/>
      <geometry>
        <mesh filename="package://el_a3_description/meshes/part_15.stl"/>
      </geometry>
      <material name="blue"/>
    </visual>
    <collision>
      <origin rpy="-3.14159 0 0" xyz="0 0 -0.0755"/>
      <geometry>
        <mesh filename="package://el_a3_description/meshes/part_15.stl"/>
      </geometry>
    </collision>
    <!-- Part manifold_solid_brep_40_1 -->
    <visual>
      <origin rpy="-3.14159 0 0" xyz="0 0 -0.0755"/>
      <geometry>
        <mesh filename="package://el_a3_description/meshes/manifold_solid_brep_40_1.stl"/>
      </geometry>
      <material name="gray"/>
    </visual>
    <collision>
      <origin rpy="-3.14159 0 0" xyz="0 0 -0.0755"/>
      <geometry>
        <mesh filename="package://el_a3_description/meshes/manifold_solid_brep_40_1.stl"/>
      </geometry>
    </collision>
  </link>
  <!-- End Effector link -->
  <link name="end_effector"/>
  <!-- Joints -->
  <!-- Joint L1 (RS00 Motor 1) -->
  <joint name="L1_joint" type="revolute">
    <origin rpy="0 0 0" xyz="0 0 0.006"/>
    <parent link="l1_urdf_urdf_asm"/>
    <child link="l1_link_urdf_asm"/>
    <axis xyz="0 0 1"/>
    <limit effort="14" lower="-2.79253" upper="2.79253" velocity="33"/>
    <dynamics damping="0.1" friction="0.1"/>
  </joint>
  <!-- Joint L2 (RS00 Motor 2) -->
  <joint name="L2_joint" type="revolute">
    <origin rpy="1.5708 0 0" xyz="-0.01 -0.0006 0.064"/>
    <parent link="l1_link_urdf_asm"/>
    <child link="l2_l3_urdf_asm"/>
    <axis xyz="0 0 1"/>
    <limit effort="14" lower="0" upper="3.66519" velocity="33"/>
    <dynamics damping="0.1" friction="0.1"/>
  </joint>
  <!-- Joint L3 (RS00 Motor 3) -->
  <joint name="L3_joint" type="revolute">
    <origin rpy="0 0 0" xyz="0.19 0 0.0518"/>
    <parent link="l2_l3_urdf_asm"/>
    <child link="l3_lnik_urdf_asm"/>
    <axis xyz="0 0 1"/>
    <limit effort="14" lower="-4.01426" upper="0" velocity="33"/>
    <dynamics damping="0.1" friction="0.1"/>
  </joint>
  <!-- Joint L4 (${wrist_motor_type} Motor 4) -->
  <joint name="L4_joint" type="revolute">
    <origin rpy="0 0 0" xyz="-0.185 0.064 -0.0518"/>
    <parent link="l3_lnik_urdf_asm"/>
    <child link="l4_l5_urdf_asm"/>
    <axis xyz="0 0 1"/>
    <limit effort="6.0" lower="-1.5708" upper="1.5708" velocity="50"/>
    <dynamics damping="0.05" friction="0.05"/>
  </joint>
  <!-- Joint L5 (${wrist_motor_type} Motor 5) -->
  <joint name="L5_joint" type="revolute">
    <origin rpy="1.5708 0 0" xyz="-0.0492 0.038 0"/>
    <parent link="l4_l5_urdf_asm"/>
    <child link="part_9"/>
    <axis xyz="0 0 1"/>
    <limit effort="6.0" lower="-1.5708" upper="1.5708" velocity="50"/>
    <dynamics damping="0.05" friction="0.05"/>
  </joint>
  <!-- Joint L6 (${wrist_motor_type} Motor 6) -->
  <joint name="L6_joint" type="revolute">
    <origin rpy="-1.5708 0 -1.5708" xyz="0.00805 0 0.038"/>
    <parent link="part_9"/>
    <child link="l5_l6_urdf_asm"/>
    <axis xyz="0 0 1"/>
    <limit effort="6.0" lower="-1.5708" upper="1.5708" velocity="50"/>
    <dynamics damping="0.05" friction="0.05"/>
  </joint>
  <!-- End Effector joint (fixed to last arm link, defines TCP for MoveIt planning) -->
  <joint name="end_effector_joint" type="fixed">
    <origin rpy="0 0 0" xyz="0 0 -0.074"/>
    <parent link="l5_l6_urdf_asm"/>
    <child link="end_effector"/>
  </joint>
  <!-- Joint L7 (${wrist_motor_type} Motor 7 - Gripper, separate kinematic branch) -->
  <joint name="L7_joint" type="revolute">
    <origin rpy="0 0 0" xyz="0 0 -0.074"/>
    <parent link="l5_l6_urdf_asm"/>
    <child link="gripper_link"/>
    <axis xyz="0 0 1"/>
    <limit effort="6.0" lower="-1.5708" upper="1.5708" velocity="50"/>
    <dynamics damping="0.05" friction="0.05"/>
  </joint>
  <link name="gripper_link">
    <inertial>
      <mass value="0.05"/>
      <origin xyz="0 0 0"/>
      <inertia ixx="0.0001" ixy="0" ixz="0" iyy="0.0001" iyz="0" izz="0.0001"/>
    </inertial>
  </link>
  <ros2_control name="RsA3System" type="system">
    <hardware>
      <plugin>el_a3_hardware/RsA3HardwareInterface</plugin>
      <param name="can_interface">can0</param>
      <param name="host_can_id">253</param>
      <param name="position_kp">100.0</param>
      <param name="position_kd">4.0</param>
      <param name="velocity_limit">10.0</param>
      <!-- S-curve trajectory planning parameters -->
      <param name="s_curve_enabled">false</param>
      <!-- Temporarily disabled to avoid conflict with MoveIt trajectory -->
      <param name="max_velocity">3.0</param>
      <!-- Max velocity limit rad/s -->
      <param name="max_acceleration">15.0</param>
      <!-- Max acceleration limit rad/s² -->
      <param name="max_jerk">50.0</param>
      <!-- Max jerk limit rad/s³ -->
      <!-- Fallback smoothing filter parameters (used when S-curve is disabled) -->
      <param name="smoothing_alpha">0.8</param>
      <!-- Low-pass filter coefficient (0.8 = near-passthrough, teleop already smooths) -->
      <!-- Gravity compensation feedforward parameters (100% gravity as feedforward torque, matching zero-torque mode) -->
      <param name="gravity_feedforward_ratio">0.0</param>
      <!-- 85% gravity compensation ratio, avoid over-compensation oscillation -->
      <!-- Zero-torque mode parameters -->
      <param name="zero_torque_kd">0.3</param>
      <!-- Zero-torque mode damping coefficient -->
      <!-- Pinocchio dynamics model configuration -->
      <param name="urdf_path">/home/wy/RS/A3/install/el_a3_description/share/el_a3_description/urdf/el_a3.urdf</param>
      <param name="use_pinocchio_gravity">true</param>
      <!-- Enable full dynamics gravity compensation -->
      <!-- Inertia parameter config file path (generated by inertia_calibration.py) -->
      <param name="inertia_config_path">/home/wy/RS/A3/install/el_a3_description/share/el_a3_description/config/inertia_params.yaml</param>
      <!-- Inertia parameter scale factors (legacy method, kept for backward compatibility) -->
      <param name="inertia_scale_L1_mass">1.0000</param>
      <param name="inertia_scale_L2_mass">2.0000</param>
      <param name="inertia_scale_L3_mass">0.6839</param>
      <param name="inertia_scale_L4_mass">0.3500</param>
      <param name="inertia_scale_L5_mass">1.0000</param>
      <param name="inertia_scale_L6_mass">1.0000</param>
      <!-- L1 joint - Base rotation around Z-axis, no gravity effect -->
      <param name="gravity_comp_L1_sin">0.0</param>
      <param name="gravity_comp_L1_cos">0.0</param>
      <param name="gravity_comp_L1_offset">0.0</param>
      <!-- L2 joint - Upper arm pitch, bears primary gravity load -->
      <!-- τ = m*g*L*sin(θ), needs calibration based on actual measurements -->
      <param name="gravity_comp_L2_sin">3.5</param>
      <param name="gravity_comp_L2_cos">0.0</param>
      <param name="gravity_comp_L2_offset">0.0</param>
      <!-- L3 joint - Forearm pitch -->
      <param name="gravity_comp_L3_sin">2.0</param>
      <param name="gravity_comp_L3_cos">0.0</param>
      <param name="gravity_comp_L3_offset">0.0</param>
      <!-- L4 joint - Wrist Roll -->
      <param name="gravity_comp_L4_sin">0.0</param>
      <param name="gravity_comp_L4_cos">0.0</param>
      <param name="gravity_comp_L4_offset">0.0</param>
      <!-- L5 joint - Wrist Pitch -->
      <param name="gravity_comp_L5_sin">0.3</param>
      <param name="gravity_comp_L5_cos">0.0</param>
      <param name="gravity_comp_L5_offset">0.0</param>
      <!-- L6 joint - Wrist Yaw -->
      <param name="gravity_comp_L6_sin">0.0</param>
      <param name="gravity_comp_L6_cos">0.0</param>
      <param name="gravity_comp_L6_offset">0.0</param>
    </hardware>
    <!-- Joint L1 - RS00 Motor 1 -->
    <joint name="L1_joint">
      <param name="motor_id">1</param>
      <param name="motor_type">RS00</param>
      <param name="position_offset">0.0</param>
      <param name="direction">-1.0</param>
      <command_interface name="position">
        <param name="min">-2.79253</param>
        <param name="max">2.79253</param>
      </command_interface>
      <command_interface name="velocity">
        <param name="min">-33.0</param>
        <param name="max">33.0</param>
      </command_interface>
      <command_interface name="effort">
        <param name="min">-14.0</param>
        <param name="max">14.0</param>
      </command_interface>
      <state_interface name="position"/>
      <state_interface name="velocity"/>
      <state_interface name="effort"/>
    </joint>
    <!-- Joint L2 - RS00 Motor 2 -->
    <joint name="L2_joint">
      <param name="motor_id">2</param>
      <param name="motor_type">RS00</param>
      <param name="position_offset">0.0</param>
      <param name="direction">1.0</param>
      <command_interface name="position">
        <param name="min">0</param>
        <param name="max">3.66519</param>
      </command_interface>
      <command_interface name="velocity">
        <param name="min">-33.0</param>
        <param name="max">33.0</param>
      </command_interface>
      <command_interface name="effort">
        <param name="min">-14.0</param>
        <param name="max">14.0</param>
      </command_interface>
      <state_interface name="position"/>
      <state_interface name="velocity"/>
      <state_interface name="effort"/>
    </joint>
    <!-- Joint L3 - RS00 Motor 3 -->
    <joint name="L3_joint">
      <param name="motor_id">3</param>
      <param name="motor_type">RS00</param>
      <param name="position_offset">0.0</param>
      <param name="direction">-1.0</param>
      <command_interface name="position">
        <param name="min">-4.01426</param>
        <param name="max">0</param>
      </command_interface>
      <command_interface name="velocity">
        <param name="min">-33.0</param>
        <param name="max">33.0</param>
      </command_interface>
      <command_interface name="effort">
        <param name="min">-14.0</param>
        <param name="max">14.0</param>
      </command_interface>
      <state_interface name="position"/>
      <state_interface name="velocity"/>
      <state_interface name="effort"/>
    </joint>
    <!-- Joint L4 - ${wrist_motor_type} Motor 4 -->
    <joint name="L4_joint">
      <param name="motor_id">4</param>
      <param name="motor_type">EL05</param>
      <param name="position_offset">0.0</param>
      <param name="direction">1.0</param>
      <param name="kp">100.0</param>
      <param name="kd">4.0</param>
      <command_interface name="position">
        <param name="min">-1.5708</param>
        <param name="max">1.5708</param>
      </command_interface>
      <command_interface name="velocity">
        <param name="min">-50.0</param>
        <param name="max">50.0</param>
      </command_interface>
      <command_interface name="effort">
        <param name="min">-6.0</param>
        <param name="max">6.0</param>
      </command_interface>
      <state_interface name="position"/>
      <state_interface name="velocity"/>
      <state_interface name="effort"/>
    </joint>
    <!-- Joint L5 - ${wrist_motor_type} Motor 5 -->
    <joint name="L5_joint">
      <param name="motor_id">5</param>
      <param name="motor_type">EL05</param>
      <param name="position_offset">0.0</param>
      <param name="direction">-1.0</param>
      <param name="kp">100.0</param>
      <param name="kd">4.0</param>
      <command_interface name="position">
        <param name="min">-1.5708</param>
        <param name="max">1.5708</param>
      </command_interface>
      <command_interface name="velocity">
        <param name="min">-50.0</param>
        <param name="max">50.0</param>
      </command_interface>
      <command_interface name="effort">
        <param name="min">-6.0</param>
        <param name="max">6.0</param>
      </command_interface>
      <state_interface name="position"/>
      <state_interface name="velocity"/>
      <state_interface name="effort"/>
    </joint>
    <!-- Joint L6 - ${wrist_motor_type} Motor 6 -->
    <joint name="L6_joint">
      <param name="motor_id">6</param>
      <param name="motor_type">EL05</param>
      <param name="position_offset">0.0</param>
      <param name="direction">1.0</param>
      <param name="kp">100.0</param>
      <param name="kd">4.0</param>
      <command_interface name="position">
        <param name="min">-1.5708</param>
        <param name="max">1.5708</param>
      </command_interface>
      <command_interface name="velocity">
        <param name="min">-50.0</param>
        <param name="max">50.0</param>
      </command_interface>
      <command_interface name="effort">
        <param name="min">-6.0</param>
        <param name="max">6.0</param>
      </command_interface>
      <state_interface name="position"/>
      <state_interface name="velocity"/>
      <state_interface name="effort"/>
    </joint>
    <!-- Joint L7 - ${wrist_motor_type} Motor 7 (Gripper) -->
    <joint name="L7_joint">
      <param name="motor_id">7</param>
      <param name="motor_type">EL05</param>
      <param name="position_offset">0.0</param>
      <param name="direction">1.0</param>
      <command_interface name="position">
        <param name="min">-1.5708</param>
        <param name="max">1.5708</param>
      </command_interface>
      <command_interface name="velocity">
        <param name="min">-50.0</param>
        <param name="max">50.0</param>
      </command_interface>
      <command_interface name="effort">
        <param name="min">-6.0</param>
        <param name="max">6.0</param>
      </command_interface>
      <state_interface name="position"/>
      <state_interface name="velocity"/>
      <state_interface name="effort"/>
    </joint>
  </ros2_control>
</robot>
