<?xml version="1.0" ?>
<!-- =================================================================================== -->
<!-- |    This document was autogenerated by xacro from el_a3_description/urdf/el_a3.urdf.xacro | -->
<!-- |    EDITING THIS FILE BY HAND IS NOT RECOMMENDED                                 | -->
<!-- =================================================================================== -->
<!-- EL-A3 6-DOF Robot Arm URDF with ros2_control support -->
<!-- Updated from EDULITE-A3 model -->
<robot name="EL-A3">
  <!-- Materials -->
  <material name="orange">
    <color rgba="0.972549 0.529412 0.00392157 1"/>
  </material>
  <material name="dark_brown">
    <color rgba="0.301961 0.290196 0.262745 1"/>
  </material>

  <!-- Base link (world) -->
  <link name="base_link"/>
  <joint name="base_to_l1" type="fixed">
    <parent link="base_link"/>
    <child link="l1_urdf_urdf_asm"/>
    <origin rpy="0 0 0" xyz="0 0 0"/>
  </joint>

  <!-- Link l1_urdf_urdf_asm (Base) -->
  <link name="l1_urdf_urdf_asm">
    <inertial>
      <origin rpy="0 0 0" xyz="4.66057e-08 7.85527e-05 0.0336468"/>
      <mass value="0.498832"/>
      <inertia ixx="0.000371872" ixy="-1.33362e-08" ixz="5.96807e-10" iyy="0.000365137" iyz="-1.36721e-06" izz="0.000388475"/>
    </inertial>
    <visual>
      <origin rpy="0 0 0" xyz="-0.000643355 0 0.059"/>
      <geometry>
        <mesh filename="package://el_a3_description/meshes/l1.stl"/>
      </geometry>
      <material name="dark_brown"/>
    </visual>
    <collision>
      <origin rpy="0 0 0" xyz="-0.000643355 0 0.059"/>
      <geometry>
        <mesh filename="package://el_a3_description/meshes/l1.stl"/>
      </geometry>
    </collision>
  </link>

  <!-- Link l1_link_urdf_asm -->
  <link name="l1_link_urdf_asm">
    <inertial>
      <origin rpy="0 0 0" xyz="-0.00232762 -0.00161986 0.0421389"/>
      <mass value="0.105244"/>
      <inertia ixx="0.000163151" ixy="-3.25924e-06" ixz="1.01303e-05" iyy="9.80821e-05" iyz="1.04567e-05" izz="0.000118753"/>
    </inertial>
    <visual>
      <origin rpy="3.14159 0 0" xyz="-0.000642857 0 0.001"/>
      <geometry>
        <mesh filename="package://el_a3_description/meshes/l2.stl"/>
      </geometry>
      <material name="orange"/>
    </visual>
    <collision>
      <origin rpy="3.14159 0 0" xyz="-0.000642857 0 0.001"/>
      <geometry>
        <mesh filename="package://el_a3_description/meshes/l2.stl"/>
      </geometry>
    </collision>
  </link>

  <!-- Link l2_l3_urdf_asm -->
  <link name="l2_l3_urdf_asm">
    <inertial>
      <origin rpy="0 0 0" xyz="0.0949957 1.32911e-06 0.000626283"/>
      <mass value="0.836196"/>
      <inertia ixx="0.000419405" ixy="-4.27021e-07" ixz="-4.05336e-10" iyy="0.00708317" iyz="2.8291e-09" izz="0.00707892"/>
    </inertial>
    <visual>
      <origin rpy="-1.5708 0 0" xyz="0.009 -0.07 0"/>
      <geometry>
        <mesh filename="package://el_a3_description/meshes/l3.stl"/>
      </geometry>
      <material name="dark_brown"/>
    </visual>
    <collision>
      <origin rpy="-1.5708 0 0" xyz="0.009 -0.07 0"/>
      <geometry>
        <mesh filename="package://el_a3_description/meshes/l3.stl"/>
      </geometry>
    </collision>
  </link>

  <!-- Link l3_lnik_urdf_asm -->
  <link name="l3_lnik_urdf_asm">
    <inertial>
      <origin rpy="0 0 0" xyz="-0.0743466 -0.0535452 -0.00326782"/>
      <mass value="0.262025"/>
      <inertia ixx="0.000333463" ixy="-0.000182996" ixz="-9.89508e-06" iyy="0.00130159" iyz="1.18614e-05" izz="0.00133147"/>
    </inertial>
    <visual>
      <origin rpy="-1.5708 0 0" xyz="-0.181 -0.07 0"/>
      <geometry>
        <mesh filename="package://el_a3_description/meshes/l4.stl"/>
      </geometry>
      <material name="orange"/>
    </visual>
    <collision>
      <origin rpy="-1.5708 0 0" xyz="-0.181 -0.07 0"/>
      <geometry>
        <mesh filename="package://el_a3_description/meshes/l4.stl"/>
      </geometry>
    </collision>
  </link>

  <!-- Link l4_l5_urdf_asm -->
  <link name="l4_l5_urdf_asm">
    <inertial>
      <origin rpy="0 0 0" xyz="-0.0242818 -0.0298393 0.000368105"/>
      <mass value="0.55715"/>
      <inertia ixx="0.0006785" ixy="-0.000401622" ixz="-5.0507e-06" iyy="0.000503952" iyz="-6.21816e-06" izz="0.000993465"/>
    </inertial>
    <visual>
      <origin rpy="1.5708 0 0" xyz="0.004 0.134 0"/>
      <geometry>
        <mesh filename="package://el_a3_description/meshes/l5.stl"/>
      </geometry>
      <material name="dark_brown"/>
    </visual>
    <collision>
      <origin rpy="1.5708 0 0" xyz="0.004 0.134 0"/>
      <geometry>
        <mesh filename="package://el_a3_description/meshes/l5.stl"/>
      </geometry>
    </collision>
  </link>

  <!-- Link part_9 -->
  <link name="part_9">
    <inertial>
      <origin rpy="0 0 0" xyz="0.00527533 0 -0.0216678"/>
      <mass value="0.0392349"/>
      <inertia ixx="1.45554e-05" ixy="0" ixz="4.08768e-06" iyy="1.4787e-05" iyz="0" izz="6.36147e-06"/>
    </inertial>
    <visual>
      <origin rpy="3.14159 0 0" xyz="0.0532 0 0.173"/>
      <geometry>
        <mesh filename="package://el_a3_description/meshes/l6.stl"/>
      </geometry>
      <material name="orange"/>
    </visual>
    <collision>
      <origin rpy="3.14159 0 0" xyz="0.0532 0 0.173"/>
      <geometry>
        <mesh filename="package://el_a3_description/meshes/l6.stl"/>
      </geometry>
    </collision>
  </link>

  <!-- Link l5_l6_urdf_asm (End Effector) -->
  <link name="l5_l6_urdf_asm">
    <inertial>
      <origin rpy="0 0 0" xyz="8.14367e-06 8.87434e-05 0.0699256"/>
      <mass value="0.657292"/>
      <inertia ixx="0.00132624" ixy="1.41465e-05" ixz="9.49712e-08" iyy="0.00177268" iyz="-7.87717e-06" izz="0.000610685"/>
    </inertial>
    <!-- Part el05_l6 -->
    <visual>
      <origin rpy="3.14159 0 0" xyz="0 0 -0.0755"/>
      <geometry>
        <mesh filename="package://el_a3_description/meshes/el05_l6.stl"/>
      </geometry>
      <material name="dark_brown"/>
    </visual>
    <collision>
      <origin rpy="3.14159 0 0" xyz="0 0 -0.0755"/>
      <geometry>
        <mesh filename="package://el_a3_description/meshes/el05_l6.stl"/>
      </geometry>
    </collision>
    <!-- Part jaw -->
    <visual>
      <origin rpy="3.14159 0 0" xyz="0 0 -0.0755"/>
      <geometry>
        <mesh filename="package://el_a3_description/meshes/jaw.stl"/>
      </geometry>
      <material name="orange"/>
    </visual>
    <collision>
      <origin rpy="3.14159 0 0" xyz="0 0 -0.0755"/>
      <geometry>
        <mesh filename="package://el_a3_description/meshes/jaw.stl"/>
      </geometry>
    </collision>
  </link>

  <!-- End Effector link -->
  <link name="end_effector"/>

  <!-- Joints -->
  <joint name="L1_joint" type="revolute">
    <origin rpy="3.14159 0 0" xyz="0 0 0.06"/>
    <parent link="l1_urdf_urdf_asm"/>
    <child link="l1_link_urdf_asm"/>
    <axis xyz="0 0 -1"/>
    <limit effort="14" lower="-2.79253" upper="2.79253" velocity="33"/>
    <dynamics damping="0.1" friction="0.1"/>
  </joint>
  <joint name="L2_joint" type="revolute">
    <origin rpy="-1.5708 0 0" xyz="-0.00964286 0 -0.069"/>
    <parent link="l1_link_urdf_asm"/>
    <child link="l2_l3_urdf_asm"/>
    <axis xyz="0 0 1"/>
    <limit effort="14" lower="0" upper="3.66519" velocity="33"/>
    <dynamics damping="0.1" friction="0.1"/>
  </joint>
  <joint name="L3_joint" type="revolute">
    <origin rpy="0 0 0" xyz="0.19 0 0"/>
    <parent link="l2_l3_urdf_asm"/>
    <child link="l3_lnik_urdf_asm"/>
    <axis xyz="0 0 1"/>
    <limit effort="14" lower="-4.01426" upper="0" velocity="33"/>
    <dynamics damping="0.1" friction="0.1"/>
  </joint>
  <!-- Joint L4 (EL05 Motor 4) -->
  <joint name="L4_joint" type="revolute">
    <origin rpy="-3.14159 0 0" xyz="-0.185 0.064 0"/>
    <parent link="l3_lnik_urdf_asm"/>
    <child link="l4_l5_urdf_asm"/>
    <axis xyz="0 0 -1"/>
    <limit effort="6.0" lower="-1.0472" upper="1.5708" velocity="50"/>
    <dynamics damping="0.05" friction="0.05"/>
  </joint>
  <!-- Joint L5 (EL05 Motor 5) -->
  <joint name="L5_joint" type="revolute">
    <origin rpy="-1.5708 0 0" xyz="-0.0492 -0.038 0"/>
    <parent link="l4_l5_urdf_asm"/>
    <child link="part_9"/>
    <axis xyz="0 0 1"/>
    <limit effort="6.0" lower="-1.5708" upper="1.5708" velocity="50"/>
    <dynamics damping="0.05" friction="0.05"/>
  </joint>
  <!-- Joint L6 (EL05 Motor 6) -->
  <joint name="L6_joint" type="revolute">
    <origin rpy="-1.5708 0 -1.5708" xyz="0.00685 0 0.039"/>
    <parent link="part_9"/>
    <child link="l5_l6_urdf_asm"/>
    <axis xyz="0 0 1"/>
    <limit effort="6.0" lower="-1.5708" upper="1.5708" velocity="50"/>
    <dynamics damping="0.05" friction="0.05"/>
  </joint>
  <!-- End Effector joint -->
  <joint name="end_effector_joint" type="fixed">
    <origin rpy="0 0 0" xyz="0 0 -0.074"/>
    <parent link="l5_l6_urdf_asm"/>
    <child link="end_effector"/>
  </joint>
  <ros2_control name="RsA3System" type="system">
    <hardware>
      <plugin>el_a3_hardware/RsA3HardwareInterface</plugin>
      <param name="can_interface">can0</param>
      <param name="host_can_id">253</param>
      <param name="position_kp">80.0</param>
      <param name="position_kd">4.0</param>
      <param name="velocity_limit">10.0</param>
      <param name="s_curve_enabled">false</param>
      <param name="max_velocity">3.0</param>
      <param name="max_acceleration">15.0</param>
      <param name="max_jerk">50.0</param>
      <param name="smoothing_alpha">0.2</param>
      <param name="gravity_feedforward_ratio">0.5</param>
      <param name="zero_torque_kd">0.1</param>
      <!-- Pinocchio dynamics model configuration -->
      <param name="urdf_path">urdf/el_a3.urdf</param>
      <param name="use_pinocchio_gravity">true</param>
      <param name="inertia_config_path">config/inertia_params.yaml</param>
      <!-- Inertia parameter scale factors (legacy) -->
      <param name="inertia_scale_L1_mass">1.0000</param>
      <param name="inertia_scale_L2_mass">2.0000</param>
      <param name="inertia_scale_L3_mass">0.6839</param>
      <param name="inertia_scale_L4_mass">0.3500</param>
      <param name="inertia_scale_L5_mass">1.0000</param>
      <param name="inertia_scale_L6_mass">1.0000</param>
      <!-- Gravity compensation parameters -->
      <param name="gravity_comp_L1_sin">0.0</param>
      <param name="gravity_comp_L1_cos">0.0</param>
      <param name="gravity_comp_L1_offset">0.0</param>
      <param name="gravity_comp_L2_sin">3.5</param>
      <param name="gravity_comp_L2_cos">0.0</param>
      <param name="gravity_comp_L2_offset">0.0</param>
      <param name="gravity_comp_L3_sin">2.0</param>
      <param name="gravity_comp_L3_cos">0.0</param>
      <param name="gravity_comp_L3_offset">0.0</param>
      <param name="gravity_comp_L4_sin">0.0</param>
      <param name="gravity_comp_L4_cos">0.0</param>
      <param name="gravity_comp_L4_offset">0.0</param>
      <param name="gravity_comp_L5_sin">0.3</param>
      <param name="gravity_comp_L5_cos">0.0</param>
      <param name="gravity_comp_L5_offset">0.0</param>
      <param name="gravity_comp_L6_sin">0.0</param>
      <param name="gravity_comp_L6_cos">0.0</param>
      <param name="gravity_comp_L6_offset">0.0</param>
    </hardware>
    <!-- Joint L1 - RS00 Motor 1 -->
    <joint name="L1_joint">
      <param name="motor_id">1</param>
      <param name="motor_type">RS00</param>
      <param name="position_offset">0.0</param>
      <param name="direction">-1.0</param>
      <command_interface name="position">
        <param name="min">-2.79253</param>
        <param name="max">2.79253</param>
      </command_interface>
      <command_interface name="velocity">
        <param name="min">-33.0</param>
        <param name="max">33.0</param>
      </command_interface>
      <command_interface name="effort">
        <param name="min">-14.0</param>
        <param name="max">14.0</param>
      </command_interface>
      <state_interface name="position"/>
      <state_interface name="velocity"/>
      <state_interface name="effort"/>
    </joint>
    <!-- Joint L2 - RS00 Motor 2 -->
    <joint name="L2_joint">
      <param name="motor_id">2</param>
      <param name="motor_type">RS00</param>
      <param name="position_offset">0.0</param>
      <param name="direction">1.0</param>
      <command_interface name="position">
        <param name="min">0</param>
        <param name="max">3.66519</param>
      </command_interface>
      <command_interface name="velocity">
        <param name="min">-33.0</param>
        <param name="max">33.0</param>
      </command_interface>
      <command_interface name="effort">
        <param name="min">-14.0</param>
        <param name="max">14.0</param>
      </command_interface>
      <state_interface name="position"/>
      <state_interface name="velocity"/>
      <state_interface name="effort"/>
    </joint>
    <!-- Joint L3 - RS00 Motor 3 -->
    <joint name="L3_joint">
      <param name="motor_id">3</param>
      <param name="motor_type">RS00</param>
      <param name="position_offset">0.0</param>
      <param name="direction">-1.0</param>
      <command_interface name="position">
        <param name="min">-4.01426</param>
        <param name="max">0</param>
      </command_interface>
      <command_interface name="velocity">
        <param name="min">-33.0</param>
        <param name="max">33.0</param>
      </command_interface>
      <command_interface name="effort">
        <param name="min">-14.0</param>
        <param name="max">14.0</param>
      </command_interface>
      <state_interface name="position"/>
      <state_interface name="velocity"/>
      <state_interface name="effort"/>
    </joint>
    <!-- Joint L4 - EL05 Motor 4 -->
    <joint name="L4_joint">
      <param name="motor_id">4</param>
      <param name="motor_type">EL05</param>
      <param name="position_offset">0.0</param>
      <param name="direction">1.0</param>
      <command_interface name="position">
        <param name="min">-1.0472</param>
        <param name="max">1.5708</param>
      </command_interface>
      <command_interface name="velocity">
        <param name="min">-50.0</param>
        <param name="max">50.0</param>
      </command_interface>
      <command_interface name="effort">
        <param name="min">-6.0</param>
        <param name="max">6.0</param>
      </command_interface>
      <state_interface name="position"/>
      <state_interface name="velocity"/>
      <state_interface name="effort"/>
    </joint>
    <!-- Joint L5 - EL05 Motor 5 -->
    <joint name="L5_joint">
      <param name="motor_id">5</param>
      <param name="motor_type">EL05</param>
      <param name="position_offset">0.0</param>
      <param name="direction">-1.0</param>
      <command_interface name="position">
        <param name="min">-1.5708</param>
        <param name="max">1.5708</param>
      </command_interface>
      <command_interface name="velocity">
        <param name="min">-50.0</param>
        <param name="max">50.0</param>
      </command_interface>
      <command_interface name="effort">
        <param name="min">-6.0</param>
        <param name="max">6.0</param>
      </command_interface>
      <state_interface name="position"/>
      <state_interface name="velocity"/>
      <state_interface name="effort"/>
    </joint>
    <!-- Joint L6 - EL05 Motor 6 -->
    <joint name="L6_joint">
      <param name="motor_id">6</param>
      <param name="motor_type">EL05</param>
      <param name="position_offset">0.0</param>
      <param name="direction">1.0</param>
      <command_interface name="position">
        <param name="min">-1.5708</param>
        <param name="max">1.5708</param>
      </command_interface>
      <command_interface name="velocity">
        <param name="min">-50.0</param>
        <param name="max">50.0</param>
      </command_interface>
      <command_interface name="effort">
        <param name="min">-6.0</param>
        <param name="max">6.0</param>
      </command_interface>
      <state_interface name="position"/>
      <state_interface name="velocity"/>
      <state_interface name="effort"/>
    </joint>
  </ros2_control>
</robot>
